Traceback (most recent call last):
  File "C:\Users\alujan\miniconda3\lib\site-packages\jupyter_cache\executors\utils.py", line 58, in single_nb_execution
    executenb(
  File "C:\Users\alujan\miniconda3\lib\site-packages\nbclient\client.py", line 1204, in execute
    return NotebookClient(nb=nb, resources=resources, km=km, **kwargs).execute()
  File "C:\Users\alujan\miniconda3\lib\site-packages\nbclient\util.py", line 84, in wrapped
    return just_run(coro(*args, **kwargs))
  File "C:\Users\alujan\miniconda3\lib\site-packages\nbclient\util.py", line 62, in just_run
    return loop.run_until_complete(coro)
  File "C:\Users\alujan\miniconda3\lib\asyncio\base_events.py", line 649, in run_until_complete
    return future.result()
  File "C:\Users\alujan\miniconda3\lib\site-packages\nbclient\client.py", line 663, in async_execute
    await self.async_execute_cell(
  File "C:\Users\alujan\miniconda3\lib\site-packages\nbclient\client.py", line 965, in async_execute_cell
    await self._check_raise_for_error(cell, cell_index, exec_reply)
  File "C:\Users\alujan\miniconda3\lib\site-packages\nbclient\client.py", line 862, in _check_raise_for_error
    raise CellExecutionError.from_cell_and_msg(cell, exec_reply_content)
nbclient.exceptions.CellExecutionError: An error occurred while executing the following cell:
------------------
# Some initial setup
from HARK.utilities import plot_funcs_der, plot_funcs
from HARK.ConsumptionSaving.ConsIndShockModel import PerfForesightConsumerType
import pandas_datareader.data as web
from copy import deepcopy
import statsmodels.formula.api as sm
import scipy.stats as stats
import datetime as dt
import pandas as pd
import sys
import os
from matplotlib import pyplot as plt
import numpy as np

plt.style.use("seaborn-darkgrid")
palette = plt.get_cmap("Dark2")


pd.core.common.is_list_like = pd.api.types.is_list_like
------------------

[1;31m---------------------------------------------------------------------------[0m
[1;31mModuleNotFoundError[0m                       Traceback (most recent call last)
Cell [1;32mIn[1], line 4[0m
[0;32m      2[0m [38;5;28;01mfrom[39;00m [38;5;21;01mHARK[39;00m[38;5;21;01m.[39;00m[38;5;21;01mutilities[39;00m [38;5;28;01mimport[39;00m plot_funcs_der, plot_funcs
[0;32m      3[0m [38;5;28;01mfrom[39;00m [38;5;21;01mHARK[39;00m[38;5;21;01m.[39;00m[38;5;21;01mConsumptionSaving[39;00m[38;5;21;01m.[39;00m[38;5;21;01mConsIndShockModel[39;00m [38;5;28;01mimport[39;00m PerfForesightConsumerType
[1;32m----> 4[0m [38;5;28;01mimport[39;00m [38;5;21;01mpandas_datareader[39;00m[38;5;21;01m.[39;00m[38;5;21;01mdata[39;00m [38;5;28;01mas[39;00m [38;5;21;01mweb[39;00m
[0;32m      5[0m [38;5;28;01mfrom[39;00m [38;5;21;01mcopy[39;00m [38;5;28;01mimport[39;00m deepcopy
[0;32m      6[0m [38;5;28;01mimport[39;00m [38;5;21;01mstatsmodels[39;00m[38;5;21;01m.[39;00m[38;5;21;01mformula[39;00m[38;5;21;01m.[39;00m[38;5;21;01mapi[39;00m [38;5;28;01mas[39;00m [38;5;21;01msm[39;00m

[1;31mModuleNotFoundError[0m: No module named 'pandas_datareader'
ModuleNotFoundError: No module named 'pandas_datareader'

